<?xml version="1.0" ?>
<robot name="inverted_pendulum">
    <material name="Blue">
        <color rgba="0 0 0.8 1"/>
    </material>
    <material name="LightGrey">
        <color rgba="0.6 0.6 0.6 1"/>
    </material>

    <!-- Links/Joints -->
    <link name="base_link">
        <visual>
            <origin rpy="0 0 0" xyz="0 0 0.05715"/>
            <geometry>
                <box size="0.1143 0.0545 0.1143"/>
            </geometry>
            <material name="LightGrey"/>
        </visual>

        <collision>
            <origin rpy="0 0 0" xyz="0 0 0.05715"/>
            <geometry>
                <box size="0.1143 0.0545 0.1143"/>
            </geometry>
        </collision>

        <inertial>
            <origin rpy="0 0 0" xyz="0 0 0.05715"/>
            <mass value="0.2"/>
            <inertia ixx="0.000267245666667" ixy="0" ixz="0" iyy="0.000435483" iyz="0" izz="0.000267245666667"/>
        </inertial>
    </link>

    <joint name="pendulum_joint_1" type="continuous">
        <parent link="base_link"/>
        <child link="pendulum_link_1"/>
        <limit effort="2.5" velocity="10.0"/>
        <origin rpy="0 3.14159265358979323846 0" xyz="0 0.05225 0.05715"/>
        <axis xyz="0 1 0"/>
        <dynamics damping="0.2"/>
    </joint>

    <link name="pendulum_link_1">
        <visual>
            <origin rpy="0 0 0" xyz="0 0 0.5"/>
            <geometry>
                <box size="0.0402 0.05 1"/>
            </geometry>
            <material name="Blue"/>
        </visual>

        <collision>
            <origin rpy="0 0 0" xyz="0 0 0.5"/>
            <geometry>
                <box size="0.0402 0.05 1"/>
            </geometry>
        </collision>

        <inertial>
            <!-- CENTER OF MASS -->
            <origin rpy="0 0 0" xyz="0 0 0.5"/>
            <mass value="1"/>
            <!-- box inertia: 1/12*m(y^2+z^2), ... -->
            <inertia ixx="0.0835416666667" ixy="0" ixz="0" iyy="0.0834680033333" iyz="0" izz="0.000343003333333"/>
        </inertial>
    </link>
</robot>
